Workbook

Sheet Data
A1: Item number | B1: Bar code | C1: Item Name | D1: Column1
A2: 100010001 | B2: 100010001 | C2: ADA BIGONE طقم لحاف كينغ | 1 قطعة شتوي | D2: 99
A3: 100010001 | B3: 100010001 | C3: ADA BIGONE طقم لحاف كينغ | 1 قطعة شتوي | D3: 99
A4: 100010001 | B4: 100010001 | C4: ADA BIGONE طقم لحاف كينغ | 1 قطعة شتوي | D4: 99
A5: 100010002 | B5: 100010002 | C5: AFA BEN طقم لحاف كينغ | 3 قطع | D5: 129
A6: 100010002 | B6: 100010002 | C6: AFA BEN طقم لحاف كينغ | 3 قطع | D6: 129
A7: 100010002 | B7: 100010002 | C7: AFA BEN طقم لحاف كينغ | 3 قطع | D7: 129
A8: 100010002 | B8: 100010002 | C8: AFA BEN طقم لحاف كينغ | 3 قطع | D8: 129
A9: 100010003 | B9: 100010003 | C9: AID JEFFEREY GREY طقم لحاف كينغ | 3 قطع | D9: 129
A10: 100010003 | B10: 100010003 | C10: AID JEFFEREY GREY طقم لحاف كينغ | 3 قطع | D10: 129
A11: 100010003 | B11: 100010003 | C11: AID JEFFEREY GREY طقم لحاف كينغ | 3 قطع | D11: 129
A12: 100010003 | B12: 100010003 | C12: AID JEFFEREY GREY طقم لحاف كينغ | 3 قطع | D12: 129
A13: 100010004 | B13: 100010004 | C13: ARCH طقم لحاف كينغ | 5 قطع | D13: 299
... A21230: 990000239 | B21230: 990000239 | C21230: حقيبة تسوق | FLOWER GREEN | D21230: 4
A21231: CARTON00001 | B21231: CARTON00001 | C21231: CARTON JEDDAH WAREHOUSE | D21231: 0
A21232: CARTON00002 | B21232: CARTON00002 | C21232: CARTON RIYADH WAREHOUSE | D21232: 0
A21233: KIT-100010027 | B21233: KIT-100010027 | C21233: طقم لحاف كينغ | 8 قطع JULES BLUE | D21233: 299
A21234: KIT-100010027 | B21234: KIT-100010027 | C21234: طقم لحاف كينغ | 8 قطع JULES BLUE | D21234: 299
A21235: KIT-100010027 | B21235: KIT-100010027 | C21235: طقم لحاف كينغ | 8 قطع JULES BLUE | D21235: 299
A21236: KIT-100010034 | B21236: KIT-100010034 | C21236: طقم لحاف كينغ | 9 قطع MEREDITH | D21236: 695
A21237: KIT-100010034 | B21237: KIT-100010034 | C21237: طقم لحاف كينغ | 9 قطع MEREDITH | D21237: 695
A21238: KIT-100010034 | B21238: KIT-100010034 | C21238: طقم لحاف كينغ | 9 قطع MEREDITH | D21238: 695
A21239: KIT-100010051 | B21239: KIT-100010051 | C21239: طقم لحاف كينغ | 8 قطع TARA PLUM | D21239: 99
A21240: KIT-100010051 | B21240: KIT-100010051 | C21240: طقم لحاف كينغ | 8 قطع TARA PLUM | D21240: 99
A21241: KIT-100010051 | B21241: KIT-100010051 | C21241: طقم لحاف كينغ | 8 قطع TARA PLUM | D21241: 99
A21242: KIT-100010051 | B21242: KIT-100010051 | C21242: طقم لحاف كينغ | 8 قطع TARA PLUM | D21242: 99
... A22759: Ser000004 | B22759: Ser000004 | C22759: خدمة الحفر على المنتج | D22759: 9
A22760: 21578 | B22760: 100010001 | C22760: ADA BIGONE طقم لحاف كينغ | 1 قطعة شتوي | D22760: 99
A22761: 4052303 | B22761: 100010001 | C22761: ADA BIGONE طقم لحاف كينغ | 1 قطعة شتوي | D22761: 99
A22762: 2157844 | B22762: 100010001 | C22762: ADA BIGONE طقم لحاف كينغ | 1 قطعة شتوي | D22762: 99
A22763: 21307 | B22763: 100010002 | C22763: AFA BEN طقم لحاف كينغ | 3 قطع | D22763: 129
A22764: 40507 | B22764: 100010002 | C22764: AFA BEN طقم لحاف كينغ | 3 قطع | D22764: 129
A22765: 2130744 | B22765: 100010002 | C22765: AFA BEN طقم لحاف كينغ | 3 قطع | D22765: 129
A22766: 843503120789 | B22766: 100010002 | C22766: AFA BEN طقم لحاف كينغ | 3 قطع | D22766: 129
A22767: 21309 | B22767: 100010003 | C22767: AID JEFFEREY GREY طقم لحاف كينغ | 3 قطع | D22767: 129
A22768: 40509 | B22768: 100010003 | C22768: AID JEFFEREY GREY طقم لحاف كينغ | 3 قطع | D22768: 129
A22769: 2130944 | B22769: 100010003 | C22769: AID JEFFEREY GREY طقم لحاف كينغ | 3 قطع | D22769: 129
A22770: 843503120802 | B22770: 100010003 | C22770: AID JEFFEREY GREY طقم لحاف كينغ | 3 قطع | D22770: 129
A22771: 22127 | B22771: 100010004 | C22771: ARCH طقم لحاف كينغ | 5 قطع | D22771: 299
... A23636: 15504 | B23636: 100010290 | C23636: طقم لحاف كينغ | 3 قطع ALEXA | D23636: 395
...

Sheet محضر جرد معرض البساتين مول
A1: SCAN | B1: Item Number | C1: Item Name | D1: Qty | E1: Selling | F1: ملاحظات
B2: =IFERROR(VLOOKUP(A2,AxTable1[[Item number]:[Bar code]],2,0),"") | C2: =IFERROR(VLOOKUP(A2,AxTable1[],3,0),"") | E2: =IFERROR(VLOOKUP(A2,Data!A2:D45517,4,0),"")
B3: =IFERROR(VLOOKUP(A3,AxTable1[[Item number]:[Bar code]],2,0),"") | C3: =IFERROR(VLOOKUP(A3,AxTable1[],3,0),"") | E3: =IFERROR(VLOOKUP(A3,Data!A3:D45518,4,0),"")
B4: =IFERROR(VLOOKUP(A4,AxTable1[[Item number]:[Bar code]],2,0),"") | C4: =IFERROR(VLOOKUP(A4,AxTable1[],3,0),"") | E4: =IFERROR(VLOOKUP(A4,Data!A4:D45519,4,0),"")
B5: =IFERROR(VLOOKUP(A5,AxTable1[[Item number]:[Bar code]],2,0),"") | C5: =IFERROR(VLOOKUP(A5,AxTable1[],3,0),"") | E5: =IFERROR(VLOOKUP(A5,Data!A5:D45520,4,0),"")
B6: =IFERROR(VLOOKUP(A6,AxTable1[[Item number]:[Bar code]],2,0),"") | C6: =IFERROR(VLOOKUP(A6,AxTable1[],3,0),"") | E6: =IFERROR(VLOOKUP(A6,Data!A6:D45521,4,0),"")
B7: =IFERROR(VLOOKUP(A7,AxTable1[[Item number]:[Bar code]],2,0),"") | C7: =IFERROR(VLOOKUP(A7,AxTable1[],3,0),"") | E7: =IFERROR(VLOOKUP(A7,Data!A7:D45522,4,0),"")
B8: =IFERROR(VLOOKUP(A8,AxTable1[[Item number]:[Bar code]],2,0),"") | C8: =IFERROR(VLOOKUP(A8,AxTable1[],3,0),"") | E8: =IFERROR(VLOOKUP(A8,Data!A8:D45523,4,0),"")
B9: =IFERROR(VLOOKUP(A9,AxTable1[[Item number]:[Bar code]],2,0),"") | C9: =IFERROR(VLOOKUP(A9,AxTable1[],3,0),"") | E9: =IFERROR(VLOOKUP(A9,Data!A9:D45524,4,0),"")
B10: =IFERROR(VLOOKUP(A10,AxTable1[[Item number]:[Bar code]],2,0),"") | C10: =IFERROR(VLOOKUP(A10,AxTable1[],3,0),"") | E10: =IFERROR(VLOOKUP(A10,Data!A10:D45525,4,0),"")
B11: =IFERROR(VLOOKUP(A11,AxTable1[[Item number]:[Bar code]],2,0),"") | C11: =IFERROR(VLOOKUP(A11,AxTable1[],3,0),"") | E11: =IFERROR(VLOOKUP(A11,Data!A11:D45526,4,0),"")
B12: =IFERROR(VLOOKUP(A12,AxTable1[[Item number]:[Bar code]],2,0),"") | C12: =IFERROR(VLOOKUP(A12,AxTable1[],3,0),"") | E12: =IFERROR(VLOOKUP(A12,Data!A12:D45527,4,0),"")
B13: =IFERROR(VLOOKUP(A13,AxTable1[[Item number]:[Bar code]],2,0),"") | C13: =IFERROR(VLOOKUP(A13,AxTable1[],3,0),"") | E13: =IFERROR(VLOOKUP(A13,Data!A13:D45528,4,0),"")
... B201: =IFERROR(VLOOKUP(A201,AxTable1[[Item number]:[Bar code]],2,0),"") | C201: =IFERROR(VLOOKUP(A201,AxTable1[],3,0),"") | E201: =IFERROR(VLOOKUP(A201,Data!A201:D45716,4,0),"")
B202: =IFERROR(VLOOKUP(A202,AxTable1[[Item number]:[Bar code]],2,0),"") | C202: =IFERROR(VLOOKUP(A202,AxTable1[],3,0),"") | E202: =IFERROR(VLOOKUP(A202,Data!A202:D45717,4,0),"") | F202: حذف
B203: =IFERROR(VLOOKUP(A203,AxTable1[[Item number]:[Bar code]],2,0),"") | C203: =IFERROR(VLOOKUP(A203,AxTable1[],3,0),"") | E203: =IFERROR(VLOOKUP(A203,Data!A203:D45718,4,0),"")
B204: =IFERROR(VLOOKUP(A204,AxTable1[[Item number]:[Bar code]],2,0),"") | C204: =IFERROR(VLOOKUP(A204,AxTable1[],3,0),"") | E204: =IFERROR(VLOOKUP(A204,Data!A204:D45719,4,0),"")
B205: =IFERROR(VLOOKUP(A205,AxTable1[[Item number]:[Bar code]],2,0),"") | C205: =IFERROR(VLOOKUP(A205,AxTable1[],3,0),"") | E205: =IFERROR(VLOOKUP(A205,Data!A205:D45720,4,0),"") | F205: حذف
B206: =IFERROR(VLOOKUP(A206,AxTable1[[Item number]:[Bar code]],2,0),"") | C206: =IFERROR(VLOOKUP(A206,AxTable1[],3,0),"") | E206: =IFERROR(VLOOKUP(A206,Data!A206:D45721,4,0),"")
B207: =IFERROR(VLOOKUP(A207,AxTable1[[Item number]:[Bar code]],2,0),"") | C207: =IFERROR(VLOOKUP(A207,AxTable1[],3,0),"") | E207: =IFERROR(VLOOKUP(A207,Data!A207:D45722,4,0),"")
B208: =IFERROR(VLOOKUP(A208,AxTable1[[Item number]:[Bar code]],2,0),"") | C208: =IFERROR(VLOOKUP(A208,AxTable1[],3,0),"") | E208: =IFERROR(VLOOKUP(A208,Data!A208:D45723,4,0),"")
B209: =IFERROR(VLOOKUP(A209,AxTable1[[Item number]:[Bar code]],2,0),"") | C209: =IFERROR(VLOOKUP(A209,AxTable1[],3,0),"") | E209: =IFERROR(VLOOKUP(A209,Data!A209:D45724,4,0),"")
B210: =IFERROR(VLOOKUP(A210,AxTable1[[Item number]:[Bar code]],2,0),"") | C210: =IFERROR(VLOOKUP(A210,AxTable1[],3,0),"") | E210: =IFERROR(VLOOKUP(A210,Data!A210:D45725,4,0),"")
B211: =IFERROR(VLOOKUP(A211,AxTable1[[Item number]:[Bar code]],2,0),"") | C211: =IFERROR(VLOOKUP(A211,AxTable1[],3,0),"") | E211: =IFERROR(VLOOKUP(A211,Data!A211:D45726,4,0),"")
B212: =IFERROR(VLOOKUP(A212,AxTable1[[Item number]:[Bar code]],2,0),"") | C212: =IFERROR(VLOOKUP(A212,AxTable1[],3,0),"") | E212: =IFERROR(VLOOKUP(A212,Data!A212:D45727,4,0),"")
B213: =IFERROR(VLOOKUP(A213,AxTable1[[Item number]:[Bar code]],2,0),"") | C213: =IFERROR(VLOOKUP(A213,AxTable1[],3,0),"") | E213: =IFERROR(VLOOKUP(A213,Data!A213:D45728,4,0),"") | F213: حذف
B214: =IFERROR(VLOOKUP(A214,AxTable1[[Item number]:[Bar code]],2,0),"") | C214: =IFERROR(VLOOKUP(A214,AxTable1[],3,0),"") | E214: =IFERROR(VLOOKUP(A214,Data!A214:D45729,4,0),"")
B215: =IFERROR(VLOOKUP(A215,AxTable1[[Item number]:[Bar code]],2,0),"") | C215: =IFERROR(VLOOKUP(A215,AxTable1[],3,0),"") | E215: =IFERROR(VLOOKUP(A215,Data!A215:D45730,4,0),"")
B216: =IFERROR(VLOOKUP(A216,AxTable1[[Item number]:[Bar code]],2,0),"") | C216: =IFERROR(VLOOKUP(A216,AxTable1[],3,0),"") | E216: =IFERROR(VLOOKUP(A216,Data!A216:D45731,4,0),"")
B217: =IFERROR(VLOOKUP(A217,AxTable1[[Item number]:[Bar code]],2,0),"") | C217: =IFERROR(VLOOKUP(A217,AxTable1[],3,0),"") | E217: =IFERROR(VLOOKUP(A217,Data!A217:D45732,4,0),"")
B218: =IFERROR(VLOOKUP(A218,AxTable1[[Item number]:[Bar code]],2,0),"") | C218: =IFERROR(VLOOKUP(A218,AxTable1[],3,0),"") | E218: =IFERROR(VLOOKUP(A218,Data!A218:D45733,4,0),"")
B219: =IFERROR(VLOOKUP(A219,AxTable1[[Item number]:[Bar code]],2,0),"") | C219: =IFERROR(VLOOKUP(A219,AxTable1[],3,0),"") | E219: =IFERROR(VLOOKUP(A219,Data!A219:D45734,4,0),"")
B220: =IFERROR(VLOOKUP(A220,AxTable1[[Item number]:[Bar code]],2,0),"") | C220: =IFERROR(VLOOKUP(A220,AxTable1[],3,0),"") | E220: =IFERROR(VLOOKUP(A220,Data!A220:D45735,4,0),"")
B221: =IFERROR(VLOOKUP(A221,AxTable1[[Item number]:[Bar code]],2,0),"") | C221: =IFERROR(VLOOKUP(A221,AxTable1[],3,0),"") | E221: =IFERROR(VLOOKUP(A221,Data!A221:D45736,4,0),"")
B222: =IFERROR(VLOOKUP(A222,AxTable1[[Item number]:[Bar code]],2,0),"") | C222: =IFERROR(VLOOKUP(A222,AxTable1[],3,0),"") | E222: =IFERROR(VLOOKUP(A222,Data!A222:D45737,4,0),"")
B223: =IFERROR(VLOOKUP(A223,AxTable1[[Item number]:[Bar code]],2,0),"") | C223: =IFERROR(VLOOKUP(A223,AxTable1[],3,0),"") | E223: =IFERROR(VLOOKUP(A223,Data!A223:D45738,4,0),"")
B224: =IFERROR(VLOOKUP(A224,AxTable1[[Item number]:[Bar code]],2,0),"") | C224: =IFERROR(VLOOKUP(A224,AxTable1[],3,0),"") | E224: =IFERROR(VLOOKUP(A224,Data!A224:D45739,4,0),"")
B225: =IFERROR(VLOOKUP(A225,AxTable1[[Item number]:[Bar code]],2,0),"") | C225: =IFERROR(VLOOKUP(A225,AxTable1[],3,0),"") | E225: =IFERROR(VLOOKUP(A225,Data!A225:D45740,4,0),"")
... B268: =IFERROR(VLOOKUP(A268,AxTable1[[Item number]:[Bar code]],2,0),"") | C268: =IFERROR(VLOOKUP(A268,AxTable1[],3,0),"") | E268: =IFERROR(VLOOKUP(A268,Data!A268:D45783,4,0),"")
B269: =IFERROR(VLOOKUP(A269,AxTable1[[Item number]:[Bar code]],2,0),"") | C269: =IFERROR(VLOOKUP(A269,AxTable1[],3,0),"") | E269: =IFERROR(VLOOKUP(A269,Data!A269:D45784,4,0),"") | F269: حذف
...
